{
  "name": "Starter Cabin",
  "author": "Codex",
  "description": "A simple starter cabin with a stone floor, wood walls, and a sand roof.",
  "blocks": [
    { "x": 0, "y": 0, "z": 0, "type": "stone" },
    { "x": 1, "y": 0, "z": 0, "type": "stone" },
    { "x": 2, "y": 0, "z": 0, "type": "stone" },
    { "x": 3, "y": 0, "z": 0, "type": "stone" },
    { "x": 4, "y": 0, "z": 0, "type": "stone" },
    { "x": 0, "y": 0, "z": 1, "type": "stone" },
    { "x": 1, "y": 0, "z": 1, "type": "stone" },
    { "x": 2, "y": 0, "z": 1, "type": "stone" },
    { "x": 3, "y": 0, "z": 1, "type": "stone" },
    { "x": 4, "y": 0, "z": 1, "type": "stone" },
    { "x": 0, "y": 0, "z": 2, "type": "stone" },
    { "x": 1, "y": 0, "z": 2, "type": "stone" },
    { "x": 2, "y": 0, "z": 2, "type": "stone" },
    { "x": 3, "y": 0, "z": 2, "type": "stone" },
    { "x": 4, "y": 0, "z": 2, "type": "stone" },
    { "x": 0, "y": 0, "z": 3, "type": "stone" },
    { "x": 1, "y": 0, "z": 3, "type": "stone" },
    { "x": 2, "y": 0, "z": 3, "type": "stone" },
    { "x": 3, "y": 0, "z": 3, "type": "stone" },
    { "x": 4, "y": 0, "z": 3, "type": "stone" },
    { "x": 0, "y": 0, "z": 4, "type": "stone" },
    { "x": 1, "y": 0, "z": 4, "type": "stone" },
    { "x": 2, "y": 0, "z": 4, "type": "stone" },
    { "x": 3, "y": 0, "z": 4, "type": "stone" },
    { "x": 4, "y": 0, "z": 4, "type": "stone" },

    { "x": 0, "y": 1, "z": 0, "type": "wood" },
    { "x": 1, "y": 1, "z": 0, "type": "wood" },
    { "x": 3, "y": 1, "z": 0, "type": "wood" },
    { "x": 4, "y": 1, "z": 0, "type": "wood" },
    { "x": 0, "y": 1, "z": 1, "type": "wood" },
    { "x": 4, "y": 1, "z": 1, "type": "wood" },
    { "x": 0, "y": 1, "z": 2, "type": "wood" },
    { "x": 4, "y": 1, "z": 2, "type": "wood" },
    { "x": 0, "y": 1, "z": 3, "type": "wood" },
    { "x": 4, "y": 1, "z": 3, "type": "wood" },
    { "x": 0, "y": 1, "z": 4, "type": "wood" },
    { "x": 1, "y": 1, "z": 4, "type": "wood" },
    { "x": 2, "y": 1, "z": 4, "type": "wood" },
    { "x": 3, "y": 1, "z": 4, "type": "wood" },
    { "x": 4, "y": 1, "z": 4, "type": "wood" },

    { "x": 0, "y": 2, "z": 0, "type": "wood" },
    { "x": 1, "y": 2, "z": 0, "type": "wood" },
    { "x": 3, "y": 2, "z": 0, "type": "wood" },
    { "x": 4, "y": 2, "z": 0, "type": "wood" },
    { "x": 0, "y": 2, "z": 1, "type": "wood" },
    { "x": 4, "y": 2, "z": 1, "type": "wood" },
    { "x": 0, "y": 2, "z": 2, "type": "wood" },
    { "x": 4, "y": 2, "z": 2, "type": "wood" },
    { "x": 0, "y": 2, "z": 3, "type": "wood" },
    { "x": 4, "y": 2, "z": 3, "type": "wood" },
    { "x": 0, "y": 2, "z": 4, "type": "wood" },
    { "x": 1, "y": 2, "z": 4, "type": "wood" },
    { "x": 2, "y": 2, "z": 4, "type": "wood" },
    { "x": 3, "y": 2, "z": 4, "type": "wood" },
    { "x": 4, "y": 2, "z": 4, "type": "wood" },

    { "x": 0, "y": 3, "z": 0, "type": "sand" },
    { "x": 1, "y": 3, "z": 0, "type": "sand" },
    { "x": 2, "y": 3, "z": 0, "type": "sand" },
    { "x": 3, "y": 3, "z": 0, "type": "sand" },
    { "x": 4, "y": 3, "z": 0, "type": "sand" },
    { "x": 0, "y": 3, "z": 1, "type": "sand" },
    { "x": 1, "y": 3, "z": 1, "type": "sand" },
    { "x": 2, "y": 3, "z": 1, "type": "sand" },
    { "x": 3, "y": 3, "z": 1, "type": "sand" },
    { "x": 4, "y": 3, "z": 1, "type": "sand" },
    { "x": 0, "y": 3, "z": 2, "type": "sand" },
    { "x": 1, "y": 3, "z": 2, "type": "sand" },
    { "x": 2, "y": 3, "z": 2, "type": "sand" },
    { "x": 3, "y": 3, "z": 2, "type": "sand" },
    { "x": 4, "y": 3, "z": 2, "type": "sand" },
    { "x": 0, "y": 3, "z": 3, "type": "sand" },
    { "x": 1, "y": 3, "z": 3, "type": "sand" },
    { "x": 2, "y": 3, "z": 3, "type": "sand" },
    { "x": 3, "y": 3, "z": 3, "type": "sand" },
    { "x": 4, "y": 3, "z": 3, "type": "sand" },
    { "x": 0, "y": 3, "z": 4, "type": "sand" },
    { "x": 1, "y": 3, "z": 4, "type": "sand" },
    { "x": 2, "y": 3, "z": 4, "type": "sand" },
    { "x": 3, "y": 3, "z": 4, "type": "sand" },
    { "x": 4, "y": 3, "z": 4, "type": "sand" }
  ]
}
